<?xml version="1.0" encoding="UTF-8"?>
<testng-results skipped="0" failed="2" ignored="1" total="3" passed="0">
  <reporter-output>
  </reporter-output>
  <suite name="Fake API Collection" duration-ms="5353" started-at="2020-11-11T07:16:34Z" finished-at="2020-11-11T07:16:39Z">
    <groups>
    </groups>
    <test name="Manage Tests" duration-ms="5353" started-at="2020-11-11T07:16:34Z" finished-at="2020-11-11T07:16:39Z">
      <class name="fakeTestcases.CreateUser">
        <test-method status="PASS" signature="configure()[pri:0, instance:fakeTestcases.CreateUser@add0edd]" name="configure" is-config="true" duration-ms="216" started-at="2020-11-11T12:46:33Z" finished-at="2020-11-11T12:46:34Z">
          <reporter-output>
          </reporter-output>
        </test-method> <!-- configure -->
        <test-method status="FAIL" signature="createUser_validInputs()[pri:0, instance:fakeTestcases.CreateUser@add0edd]" name="createUser_validInputs" duration-ms="2926" started-at="2020-11-11T12:46:34Z" description="Verify Creation of an User with valid inputs" finished-at="2020-11-11T12:46:36Z">
          <exception class="java.lang.AssertionError">
            <full-stacktrace>
              <![CDATA[java.lang.AssertionError
	at fakeTestcases.CreateUser.createUser_validInputs(CreateUser.java:68)
	at sun.reflect.NativeMethodAccessorImpl.invoke0(Native Method)
	at sun.reflect.NativeMethodAccessorImpl.invoke(NativeMethodAccessorImpl.java:62)
	at sun.reflect.DelegatingMethodAccessorImpl.invoke(DelegatingMethodAccessorImpl.java:43)
	at java.lang.reflect.Method.invoke(Method.java:498)
	at org.testng.internal.MethodInvocationHelper.invokeMethod(MethodInvocationHelper.java:108)
	at org.testng.internal.Invoker.invokeMethod(Invoker.java:661)
	at org.testng.internal.Invoker.invokeTestMethod(Invoker.java:869)
	at org.testng.internal.Invoker.invokeTestMethods(Invoker.java:1193)
	at org.testng.internal.TestMethodWorker.invokeTestMethods(TestMethodWorker.java:126)
	at org.testng.internal.TestMethodWorker.run(TestMethodWorker.java:109)
	at org.testng.TestRunner.privateRun(TestRunner.java:744)
	at org.testng.TestRunner.run(TestRunner.java:602)
	at org.testng.SuiteRunner.runTest(SuiteRunner.java:380)
	at org.testng.SuiteRunner.runSequentially(SuiteRunner.java:375)
	at org.testng.SuiteRunner.privateRun(SuiteRunner.java:340)
	at org.testng.SuiteRunner.run(SuiteRunner.java:289)
	at org.testng.SuiteRunnerWorker.runSuite(SuiteRunnerWorker.java:52)
	at org.testng.SuiteRunnerWorker.run(SuiteRunnerWorker.java:86)
	at org.testng.TestNG.runSuitesSequentially(TestNG.java:1301)
	at org.testng.TestNG.runSuitesLocally(TestNG.java:1226)
	at org.testng.TestNG.runSuites(TestNG.java:1144)
	at org.testng.TestNG.run(TestNG.java:1115)
	at org.testng.remote.AbstractRemoteTestNG.run(AbstractRemoteTestNG.java:115)
	at org.testng.remote.RemoteTestNG.initAndRun(RemoteTestNG.java:251)
	at org.testng.remote.RemoteTestNG.main(RemoteTestNG.java:77)
]]>
            </full-stacktrace>
          </exception> <!-- java.lang.AssertionError -->
          <reporter-output>
          </reporter-output>
        </test-method> <!-- createUser_validInputs -->
      </class> <!-- fakeTestcases.CreateUser -->
      <class name="fakeTestcases.DeleteUser">
        <test-method status="FAIL" signature="deleteUser_validInputs()[pri:0, instance:fakeTestcases.DeleteUser@4b44655e]" name="deleteUser_validInputs" duration-ms="2365" started-at="2020-11-11T12:46:36Z" description="Verify deletion of an User with valid inputs" finished-at="2020-11-11T12:46:39Z">
          <exception class="java.lang.AssertionError">
            <full-stacktrace>
              <![CDATA[java.lang.AssertionError
	at fakeTestcases.DeleteUser.deleteUser_validInputs(DeleteUser.java:70)
	at sun.reflect.NativeMethodAccessorImpl.invoke0(Native Method)
	at sun.reflect.NativeMethodAccessorImpl.invoke(NativeMethodAccessorImpl.java:62)
	at sun.reflect.DelegatingMethodAccessorImpl.invoke(DelegatingMethodAccessorImpl.java:43)
	at java.lang.reflect.Method.invoke(Method.java:498)
	at org.testng.internal.MethodInvocationHelper.invokeMethod(MethodInvocationHelper.java:108)
	at org.testng.internal.Invoker.invokeMethod(Invoker.java:661)
	at org.testng.internal.Invoker.invokeTestMethod(Invoker.java:869)
	at org.testng.internal.Invoker.invokeTestMethods(Invoker.java:1193)
	at org.testng.internal.TestMethodWorker.invokeTestMethods(TestMethodWorker.java:126)
	at org.testng.internal.TestMethodWorker.run(TestMethodWorker.java:109)
	at org.testng.TestRunner.privateRun(TestRunner.java:744)
	at org.testng.TestRunner.run(TestRunner.java:602)
	at org.testng.SuiteRunner.runTest(SuiteRunner.java:380)
	at org.testng.SuiteRunner.runSequentially(SuiteRunner.java:375)
	at org.testng.SuiteRunner.privateRun(SuiteRunner.java:340)
	at org.testng.SuiteRunner.run(SuiteRunner.java:289)
	at org.testng.SuiteRunnerWorker.runSuite(SuiteRunnerWorker.java:52)
	at org.testng.SuiteRunnerWorker.run(SuiteRunnerWorker.java:86)
	at org.testng.TestNG.runSuitesSequentially(TestNG.java:1301)
	at org.testng.TestNG.runSuitesLocally(TestNG.java:1226)
	at org.testng.TestNG.runSuites(TestNG.java:1144)
	at org.testng.TestNG.run(TestNG.java:1115)
	at org.testng.remote.AbstractRemoteTestNG.run(AbstractRemoteTestNG.java:115)
	at org.testng.remote.RemoteTestNG.initAndRun(RemoteTestNG.java:251)
	at org.testng.remote.RemoteTestNG.main(RemoteTestNG.java:77)
]]>
            </full-stacktrace>
          </exception> <!-- java.lang.AssertionError -->
          <reporter-output>
          </reporter-output>
        </test-method> <!-- deleteUser_validInputs -->
      </class> <!-- fakeTestcases.DeleteUser -->
    </test> <!-- Manage Tests -->
  </suite> <!-- Fake API Collection -->
</testng-results>
